# 异常处理

JS自身提供的异常捕获和处理机制——`try..catch..`，只能用于同步执行的代码。以下是一个例子。

```js
function sync(fn) {
    return fn();
}
try {
    sync(null);
    // Do something.
} catch (err) {
    console.log('Error: %s', err.message);
}
-- Console ------------------------------
Error: object is not a function
```

可以看到，异常会沿着代码执行路径一直冒泡，直到遇到第一个`try`语句时被捕获住。但由于异步函数会打断代码执行路径，异步函数执行过程中以及执行之后产生的异常冒泡到执行路径被打断的位置时，如果一直没有遇到`try`语句，就作为一个全局异常抛出。以下是一个例子。

```js
function async(fn, callback) {
    // Code execution path breaks here.
    setTimeout(function ()　{
        callback(fn());
    }, 0);
}
try {
    async(null, function (data) {
        // Do something.
    });
} catch (err) {
    console.log('Error: %s', err.message);
}
-- Console ------------------------------
/home/user/test.js:4
        callback(fn());
                 ^
TypeError: object is not a function
    at null._onTimeout (/home/user/test.js:4:13)
    at Timer.listOnTimeout [as ontimeout] (timers.js:110:15)
```

因为代码执行路径被打断了，我们就需要在异常冒泡到断点之前用`try`语句把异常捕获住，并通过回调函数传递被捕获的异常。于是我们可以像下边这样改造上边的例子。

```js
function async(fn, callback) {
    // Code execution path breaks here.
    setTimeout(function ()　{
        try {
            callback(null, fn());
        } catch (err) {
            callback(err);
        }
    }, 0);
}
async(null, function (err, data) {
    if (err) {
        console.log('Error: %s', err.message);
    } else {
        // Do something.
    }
});
-- Console ------------------------------
Error: object is not a function
```



可以看到，异常再次被捕获住了。在NodeJS中，几乎所有异步API都按照以上方式设计，回调函数中第一个参数都是`err`。因此我们在编写自己的异步函数时，也可以按照这种方式来处理异常，与NodeJS的设计风格保持一致。

有了异常处理方式后，我们接着可以想一想一般我们是怎么写代码的。基本上，我们的代码都是做一些事情，然后调用一个函数，然后再做一些事情，然后再调用一个函数，如此循环。如果我们写的是同步代码，只需要在代码入口点写一个`try`语句就能捕获所有冒泡上来的异常，示例如下。

```js
function main() {
    // Do something.
    syncA();
    // Do something.
    syncB();
    // Do something.
    syncC();
}
try {
    main();
} catch (err) {
    // Deal with exception.
}
```

但是，如果我们写的是异步代码，就只有呵呵了。由于每次异步函数调用都会打断代码执行路径，只能通过回调函数来传递异常，于是我们就需要在每个回调函数里判断是否有异常发生，于是只用三次异步函数调用，就会产生下边这种代码。

```js
function main(callback) {
    // Do something.
    asyncA(function (err, data) {
        if (err) {
            callback(err);
        } else {
            // Do something
            asyncB(function (err, data) {
                if (err) {
                    callback(err);
                } else {
                    // Do something
                    asyncC(function (err, data) {
                        if (err) {
                            callback(err);
                        } else {
                            // Do something
                            callback(null);
                        }
                    });
                }
            });
        }
    });
}
main(function (err) {
    if (err) {
        // Deal with exception.
    }
});
```

可以看到，回调函数已经让代码变得复杂了，而异步方式下对异常的处理更加剧了代码的复杂度。如果NodeJS的最大卖点最后变成这个样子，那就没人愿意用NodeJS了，因此接下来会介绍NodeJS提供的一些解决方案(**域**)。

## 域（Domain）

使用`domain`模块可以创建一个子域（JS子运行环境）。在子域内运行的代码可以随意抛出异常，而这些异常可以通过子域对象的`error`事件统一捕获。于是以上代码可以做如下改造：

```js
function async(request, callback) {
    // Do something.
    asyncA(request, function (data) {
        // Do something
        asyncB(request, function (data) {
            // Do something
            asyncC(request, function (data) {
                // Do something
                callback(data);
            });
        });
    });
}
http.createServer(function (request, response) {
    var d = domain.create();
    d.on('error', function () {
        response.writeHead(500);
        response.end();
    });
    d.run(function () {
        async(request, function (data) {
            response.writeHead(200);
            response.end(data);
        });
    });
});
```



## 陷阱

无论是通过`process`对象的`uncaughtException`事件捕获到全局异常，还是通过子域对象的`error`事件捕获到了子域异常，在NodeJS官方文档里都强烈建议处理完异常后立即重启程序，而不是让程序继续运行。按照官方文档的说法，发生异常后的程序处于一个不确定的运行状态，如果不立即退出的话，程序可能会发生严重内存泄漏，也可能表现得很奇怪。

但这里需要澄清一些事实。JS本身的`throw..try..catch`异常处理机制并不会导致内存泄漏，也不会让程序的执行结果出乎意料，但NodeJS并不是存粹的JS。NodeJS里大量的API内部是用C/C++实现的，因此NodeJS程序的运行过程中，代码执行路径穿梭于JS引擎内部和外部，而JS的异常抛出机制可能会打断正常的代码执行流程，导致C/C++部分的代码表现异常，进而导致内存泄漏等问题。

因此，使用`uncaughtException`或`domain`捕获异常，代码执行路径里涉及到了C/C++部分的代码时，如果不能确定是否会导致内存泄漏等问题，最好在处理完异常后重启程序比较妥当。而使用`try`语句捕获异常时一般捕获到的都是JS本身的异常，不用担心上诉问题。
